Workbook

Sheet מנוע
A1: מנוע קטן לבחירת תמהיל — סדנה 8.28 (פתור)
A2: דוגמה לימודית — נתוני הלקוח והריביות להמחשה בלבד; אינם הצעת בנק או נתוני שוק עדכניים. נתונים סינתטיים. עתיד: זה לא קוד של Mogi.
A4: נתוני התיק (סינתטיים, מתוך התיק של השלב) | E4: הצעת בנק לדוגמה, מול אומדן
A5: מחיר הנכס (₪) | B5: 2200000 | E5: בנק ההצעה | F5: b
A6: ההון העצמי של הבסיס (₪) | B6: 560000 | E6: חלק קבועה % | F6: 50
A7: חסכונות (₪) | B7: 40000 | E7: חלק פריים % | F7: 50
A8: תשלום לסגירת הלוואת הרכב (₪) | B8: 36000 | E8: חלק משתנה % | F8: 0
A9: החזר חודשי של הלוואת הרכב (₪) | B9: 1450 | E9: ריבית קבועה בהצעה (%) | F9: 4.35
A10: חודשים שנשארו להלוואת הרכב | B10: 26 | E10: ריבית פריים בהצעה (%) | F10: 4.65
A11: הכנסה נטו של לווה 1 (₪) | B11: 12400 | E11: ריבית משתנה בהצעה (%) | F11: 0
A12: הכנסה נטו של לווה 2 (₪) | B12: 9300
A13: הכנסת הורה, אם מצטרף (₪) | B13: 4000 | E13: אומדן: ההחזר הראשון (₪) | F13: =IF($F$6>0,ROUND(-PMT(INDEX($C$28:$C$31,MATCH($F$5,$A$28:$A$31,0))/1200,$B$39,ROUND(($B$5-$B$6)*$F$6/100,2)),2),0)+IF($F$7>0,ROUND(-PMT(INDEX($D$28:$D$31,MATCH($F$5,$A$28:$A$31,0))/1200,$B$39,ROUND(($B$5-$B$6)*$F$7/100,2)),2),0)+IF($F$8>0,ROUND(-PMT(INDEX($E$28:$E$31,MATCH($F$5,$A$28:$A$31,0))/1200,$B$39,ROUND(($B$5-$B$6)*$F$8/100,2)),2),0) -> 8310.78
A14: ההחזר המרבי שהלקוח קבע (₪) | B14: 8300 | E14: הצעה: ההחזר הראשון (₪) | F14: =IF($F$6>0,ROUND(-PMT($F$9/1200,$B$39,ROUND(($B$5-$B$6)*$F$6/100,2)),2),0)+IF($F$7>0,ROUND(-PMT($F$10/1200,$B$39,ROUND(($B$5-$B$6)*$F$7/100,2)),2),0)+IF($F$8>0,ROUND(-PMT($F$11/1200,$B$39,ROUND(($B$5-$B$6)*$F$8/100,2)),2),0) -> 8310.28
A15: יעד יחס ההחזר של הלקוח (%) | B15: 40 | E15: הפער בהחזר הראשון (₪) | F15: =F14-F13 -> -0.5
E16: אומדן: סך התשלומים (₪) | F16: =(IF($F$6>0,-PMT(INDEX($C$28:$C$31,MATCH($F$5,$A$28:$A$31,0))/1200,$B$39,ROUND(($B$5-$B$6)*$F$6/100,2)),0)+IF($F$7>0,-PMT(INDEX($D$28:$D$31,MATCH($F$5,$A$28:$A$31,0))/1200,$B$39,ROUND(($B$5-$B$6)*$F$7/100,2)),0)+IF($F$8>0,-PMT(INDEX($E$28:$E$31,MATCH($F$5,$A$28:$A$31,0))/1200,$B$39,ROUND(($B$5-$B$6)*$F$8/100,2)),0))*$B$39 -> 2991879.3
A17: הבחירות שלכם — מיצוב הבקשה (שנו כאן) | E17: הצעה: סך התשלומים (₪) | F17: =(IF($F$6>0,-PMT($F$9/1200,$B$39,ROUND(($B$5-$B$6)*$F$6/100,2)),0)+IF($F$7>0,-PMT($F$10/1200,$B$39,ROUND(($B$5-$B$6)*$F$7/100,2)),0)+IF($F$8>0,-PMT($F$11/1200,$B$39,ROUND(($B$5-$B$6)*$F$8/100,2)),0))*$B$39 -> 2991700.3
A18: הון עצמי נוסף מהחסכונות (₪) | B18: 20000 | C18: הערך ההתחלתי הוא הבחירה של שיעור 8.28 | E18: הפער בסך התשלומים (₪) | F18: =F17-F16 -> -179.03945
A19: סוגרים את הלוואת הרכב? (1 כן, 0 לא) | B19: 0
A20: הורה מצטרף כלווה? (1 כן, 0 לא) | B20: 0
A21: בנק (a, b, c או d) | B21: a | C21: ארבעה בנקים בדויים
A22: משקל: ההחזר הראשון | B22: 40 | C22: להדגמה: לא החלטה של Mogi
A23: משקל: סך התשלומים | B23: 30
A24: משקל: החשיפה | B24: 30
A26: הבנקים הבדויים: מחירון (אחוז לשנה) וקווי סירוב
A27: קוד | B27: שם | C27: קבועה | D27: פריים | E27: משתנה | F27: סירוב ביחס החזר (%) | G27: סירוב בשיעור מימון (%)
A28: a | B28: בנק א׳ | C28: 4.4 | D28: 4.6 | E28: 4.1 | F28: 45 | G28: 75
A29: b | B29: בנק ב׳ | C29: 4.3 | D29: 4.7 | E29: 4 | F29: 50 | G29: 75
A30: c | B30: בנק ג׳ | C30: 4.35 | D30: 4.55 | E30: 4.2 | F30: 50 | G30: 75
A31: d | B31: בנק ד׳ | C31: 4.45 | D31: 4.65 | E31: 4.15 | F31: 50 | G31: 70
A33: הכללים (כפי שתועדו בקורס; הקווים של הרגולציה: לא אומת)
A34: תקרת שיעור מימון (%) | B34: 75
A35: תקרת יחס ההחזר (%) | B35: 50
A36: החלק המרבי בריבית משתנה: מונה | B36: 2
A37: החלק המרבי בריבית משתנה: מכנה | B37: 3
A38: התקופה המרבית (חודשים) | B38: 360
A39: התקופה של כל מסלול בחיפוש (חודשים) | B39: 360
A40: תרחיש לחץ: פריים עולה (נקודות אחוז, מהשנה השנייה) | B40: 2
A41: תרחיש לחץ: העוגן עולה בעדכון (נקודות אחוז) | B41: 2
A42: חודשים בין עדכוני הריבית במסלול משתנה | B42: 60
A44: מיצוב: מהבחירות לבקשה
...

Sheet בדיקה
A1: הגיליון מול המנוע של הקורס, לקלט ההתחלתי
A2: עמודה C היא התוצאה של המנוע של הקורס (מחושבת בקוד, ונבדקת פעמיים). הערכים נכונים רק לקלט ההתחלתי: אם שיניתם בחירה, ההפרשים צפויים.
A4: מה נבדק | B4: הגיליון | C4: המנוע | D4: הפרש | E4: סבילות | F4: תקין?
A5: כמה מועמדים ברשת | B5: ='מנוע'!$B$59 -> 66 | C5: 66 | D5: =IF(ISNUMBER(B5),B5-C5,"") -> 0 | E5: 0 | F5: =IF(ISNUMBER(D5),IF(ABS(D5)<=E5,"✓","✗"),"✗") -> ✓
A6: כמה אפשריים | B6: ='מנוע'!$B$60 -> 14 | C6: 14 | D6: =IF(ISNUMBER(B6),B6-C6,"") -> 0 | E6: 0 | F6: =IF(ISNUMBER(D6),IF(ABS(D6)<=E6,"✓","✗"),"✗") -> ✓
A7: כמה יעילים | B7: ='מנוע'!$B$61 -> 6 | C7: 6 | D7: =IF(ISNUMBER(B7),B7-C7,"") -> 0 | E7: 0 | F7: =IF(ISNUMBER(D7),IF(ABS(D7)<=E7,"✓","✗"),"✗") -> ✓
A8: המועמד שנבחר | B8: ='מנוע'!$B$62 -> g40-0-60 | C8: g40-0-60 | F8: =IF(B8=C8,"✓","✗") -> ✓
A9: ההחזר הראשון של הנבחר | B9: ='מנוע'!$B$63 -> 7941.62 | C9: 7941.62 | D9: =IF(ISNUMBER(B9),B9-C9,"") -> 0 | E9: 0.05 | F9: =IF(ISNUMBER(D9),IF(ABS(D9)<=E9,"✓","✗"),"✗") -> ✓
A10: סך התשלומים של הנבחר | B10: ='מנוע'!$B$64 -> 2858982.8 | C10: 2858982.6 | D10: =IF(ISNUMBER(B10),B10-C10,"") -> 0.18147512 | E10: 6 | F10: =IF(ISNUMBER(D10),IF(ABS(D10)<=E10,"✓","✗"),"✗") -> ✓
A11: החשיפה של הנבחר | B11: ='מנוע'!$B$65 -> 1030.7318 | C11: 1030.73 | D11: =IF(ISNUMBER(B11),B11-C11,"") -> 0.0017917465 | E11: 10 | F11: =IF(ISNUMBER(D11),IF(ABS(D11)<=E11,"✓","✗"),"✗") -> ✓
A12: נפסלו: סכום המסלולים שווה להלוואה | B12: ='מנוע'!$B$72 -> 0 | C12: 0 | D12: =IF(ISNUMBER(B12),B12-C12,"") -> 0 | E12: 0 | F12: =IF(ISNUMBER(D12),IF(ABS(D12)<=E12,"✓","✗"),"✗") -> ✓
A13: נפסלו: ההון העצמי קיים | B13: ='מנוע'!$B$73 -> 0 | C13: 0 | D13: =IF(ISNUMBER(B13),B13-C13,"") -> 0 | E13: 0 | F13: =IF(ISNUMBER(D13),IF(ABS(D13)<=E13,"✓","✗"),"✗") -> ✓
A14: נפסלו: שיעור מימון עד התקרה | B14: ='מנוע'!$B$74 -> 0 | C14: 0 | D14: =IF(ISNUMBER(B14),B14-C14,"") -> 0 | E14: 0 | F14: =IF(ISNUMBER(D14),IF(ABS(D14)<=E14,"✓","✗"),"✗") -> ✓
A15: נפסלו: יחס החזר עד 50% | B15: ='מנוע'!$B$75 -> 0 | C15: 0 | D15: =IF(ISNUMBER(B15),B15-C15,"") -> 0 | E15: 0 | F15: =IF(ISNUMBER(D15),IF(ABS(D15)<=E15,"✓","✗"),"✗") -> ✓
A16: נפסלו: לפחות שליש בריבית קבועה | B16: ='מנוע'!$B$76 -> 38 | C16: 38 | D16: =IF(ISNUMBER(B16),B16-C16,"") -> 0 | E16: 0 | F16: =IF(ISNUMBER(D16),IF(ABS(D16)<=E16,"✓","✗"),"✗") -> ✓
A17: נפסלו: עד 30 שנה | B17: ='מנוע'!$B$77 -> 0 | C17: 0 | D17: =IF(ISNUMBER(B17),B17-C17,"") -> 0 | E17: 0 | F17: =IF(ISNUMBER(D17),IF(ABS(D17)<=E17,"✓","✗"),"✗") -> ✓
A18: נפסלו: יחס ההחזר עד הקו של הבנק | B18: ='מנוע'!$B$78 -> 0 | C18: 0 | D18: =IF(ISNUMBER(B18),B18-C18,"") -> 0 | E18: 0 | F18: =IF(ISNUMBER(D18),IF(ABS(D18)<=E18,"✓","✗"),"✗") -> ✓
A19: נפסלו: שיעור המימון עד הקו של הבנק | B19: ='מנוע'!$B$79 -> 0 | C19: 0 | D19: =IF(ISNUMBER(B19),B19-C19,"") -> 0 | E19: 0 | F19: =IF(ISNUMBER(D19),IF(ABS(D19)<=E19,"✓","✗"),"✗") -> ✓
A20: נפסלו: ההחזר עד המרבי שהלקוח קבע | B20: ='מנוע'!$B$80 -> 1 | C20: 1 | D20: =IF(ISNUMBER(B20),B20-C20,"") -> 0 | E20: 0 | F20: =IF(ISNUMBER(D20),IF(ABS(D20)<=E20,"✓","✗"),"✗") -> ✓
A21: נפסלו: יחס ההחזר עד יעד הלקוח | B21: ='מנוע'!$B$81 -> 31 | C21: 31 | D21: =IF(ISNUMBER(B21),B21-C21,"") -> 0 | E21: 0 | F21: =IF(ISNUMBER(D21),IF(ABS(D21)<=E21,"✓","✗"),"✗") -> ✓
A22: הפער בהחזר הראשון: הצעה מול אומדן | B22: ='מנוע'!$F$15 -> -0.5 | C22: -0.5 | D22: =IF(ISNUMBER(B22),B22-C22,"") -> 1.8189894e-12 | E22: 0.05 | F22: =IF(ISNUMBER(D22),IF(ABS(D22)<=E22,"✓","✗"),"✗") -> ✓
A23: הפער בסך התשלומים: הצעה מול אומדן | B23: ='מנוע'!$F$18 -> -179.03945 | C23: -177.72 | D23: =IF(ISNUMBER(B23),B23-C23,"") -> -1.3194513 | E23: 6 | F23: =IF(ISNUMBER(D23),IF(ABS(D23)<=E23,"✓","✗"),"✗") -> ✓
A25: הגיליון מקרב את המנוע: הוא מחשב החזר מדויק (בלי עיגול כל ריבית חודשית), והמנוע מעגל כל חודש לאגורה. בסך התשלומים הפער עד כמה שקלים. בחשיפה הפער עד כעשרה שקלים, כי במנוע התשלום האחרון סוגר את היתרה, והוא גבוה בכמה שקלים מהתשלום הקבוע. הבחירה של התמהיל לא מושפעת.
A26: =IF(COUNTIF(F5:F23,"✗")=0,"✓ הכול בטווח","✗ יש פערים: בדקו את הנוסחאות או את הקלט") -> ✓ הכול בטווח

Sheet הוראות
A1: איך בונים את המנוע
A2: דוגמה לימודית — נתוני הלקוח והריביות להמחשה בלבד; אינם הצעת בנק או נתוני שוק עדכניים. נתונים סינתטיים. עתיד: זה לא קוד של Mogi.
A3: הגיליון ״מנוע״ מחזיק את התיק, את הבחירות שלכם (תאים ירוקים), את ארבעת הבנקים, את הכללים, ובסוף את הרשת: שורה לכל מועמד, בלי שום מספר שהוקלד ביד בנוסחאות.
A4: הצעדים
A5: 1 — מיצוב: בתאים B18 עד B21 בחרו הון עצמי נוסף, סגירת הלוואת הרכב, הורה ובנק. ההלוואה, שיעור המימון והכנסה הפנויה מתעדכנים (שורות 45 עד 56).
A6: 2 — תזרים: בכל שורה של הרשת, ההחזר הראשון של כל מסלול (עמודות H עד J) הוא ROUND(-PMT(ריבית/1200, חודשים, סכום), 2). סך התשלומים הוא ההחזר הלא־מעוגל כפול החודשים, וההחזר הגבוה בלחץ מחושב מחדש אחרי שהריבית עולה.
A7: 3 — חיפוש: הרשת היא כל התמהילים בצעדים של 10 אחוזים (66). אין להוסיף שורות: מרחב החיפוש הוא מה שנבדק. שורת הרשת הראשונה (89) מלאה בכל העמודות כדוגמה. עמדו על כותרת של עמודה כדי לקרוא מה היא עושה (בכותרות עם הערה), העתיקו את השורה למטה עד שורה 154, ובדקו שהתוצאות בשורות 59 עד 69 התמלאו.
A8: 4 — אילוצים: עשר עמודות (R עד AA) של 1 (נשבר) או 0 (נשמר). מועמד אפשרי כשאין בו אף 1. הסיבות מסוכמות בשורות 72 עד 81.
A9: 5 — חזית יעילה: עמודה AD סופרת כמה מועמדים אפשריים לא גרועים בשום מדד ומשופרים באחד. מועמד אפשרי שאף אחד לא שולט עליו הוא יעיל.
A10: 6 — בחירה: מנרמלים כל מדד בין אפשריים (0 הטוב, 1 הגרוע), ממוצע משוקלל לפי המשקולות בתאים B22 עד B24 (להדגמה). הציון הנמוך מנצח.
A11: 7 — הסבר: בשורות 84 עד 86, הניסוח נבנה ממספרי הגיליון. מודל שפה לעולם לא מחשב.
A12: 8 — בדיקה מול הצעת בנק: בתאים E4 עד F11 יש הצעה לדוגמה של בנק בדוי. האומדן הוא המחירון של הבנק; ההצעה היא מה שהוא כתב. הפער נמדד בהחזר הראשון ובסך התשלומים.
... A18: שינוי בחירה ישנה את התוצאות, וגם את הבדיקה: היא נכונה לקלט ההתחלתי בלבד.
